Workbook

Sheet Check Error
D2: يناير | E2: فبراير | F2: مارس | G2: ابريل | H2: مايو | I2: يونيو | J2: يوليو | K2: اغسطس | L2: سبتمبر | M2: اكتوبر | N2: نوفمبر | O2: ديسمبر | P2: Total
A3: Summary Sheet | D3: ='Summary Sheet'!D27 -> TRUE | E3: ='Summary Sheet'!E27 -> TRUE | F3: ='Summary Sheet'!F27 -> TRUE | G3: ='Summary Sheet'!G27 -> TRUE | H3: ='Summary Sheet'!H27 -> FALSE | I3: ='Summary Sheet'!I27 -> FALSE | J3: ='Summary Sheet'!J27 -> FALSE | K3: ='Summary Sheet'!K27 -> FALSE | ... Q3: ='Summary Sheet'!Q27 -> 0
D4: ='Summary Sheet'!R9 -> TRUE
D5: ='Summary Sheet'!R17 -> TRUE
D6: ='Summary Sheet'!R25 -> TRUE
D7: يناير | E7: فبراير | F7: مارس | G7: ابريل | H7: مايو | I7: يونيو | J7: يوليو | K7: اغسطس | L7: سبتمبر | M7: اكتوبر | N7: نوفمبر | O7: ديسمبر | P7: Total
A8: Annual Income (Combined) | D8: ='Annual Income (Combined)'!F35 -> TRUE | E8: ='Annual Income (Combined)'!G35 -> TRUE | F8: ='Annual Income (Combined)'!H35 -> TRUE | G8: ='Annual Income (Combined)'!I35 -> TRUE | H8: ='Annual Income (Combined)'!J35 -> TRUE | I8: ='Annual Income (Combined)'!K35 -> TRUE | J8: ='Annual Income (Combined)'!L35 -> TRUE | K8: ='Annual Income (Combined)'!M35 -> TRUE | ... P8: ='Annual Income (Combined)'!R35 -> TRUE
A14: Summary Sheet

Sheet Summary Sheet
B3: حســـــــــــــــــــــــــــــــــــــــــــــاب الصيــــــــــــــــــــــــــــــــــــــانة
B5: م | C5: المبلغ | D5: يناير | E5: فبراير | F5: مارس | G5: ابريل | H5: مايو | I5: يونيو | J5: يوليو | K5: اغسطس | L5: سبتمبر | M5: اكتوبر | N5: نوفمبر | O5: ديسمبر | Q5: Check Formula
B6: 1 | C6: فائض مرحل | D6: =January!R24 -> 45771 | E6: =D9 -> 51346 | F6: =E9 -> 30241 | G6: =F9 -> 32301 | H6: =G9 -> 32721 | I6: =H9 -> 46521 | J6: =I9 -> 52521 | K6: =J9 -> 52521 | L6: =K9 -> 52521 | ... O6: =N9 -> 52521 | Q6: =D6 -> 45771 | R6: =O6-Q6 -> 6750
B7: 2 | C7: إيرادات الشهر | D7: ='Annual income (maintenenace)'!F33 -> 15500 | E7: ='Annual income (maintenenace)'!G33+3000 -> 9500 | F7: ='Annual income (maintenenace)'!H33 -> 13200 | G7: ='Annual income (maintenenace)'!I33 -> 9500 | H7: ='Annual income (maintenenace)'!J33 -> 13800 | I7: ='Annual income (maintenenace)'!K33 -> 6000 | J7: ='Annual income (maintenenace)'!L33 -> 0 | K7: ='Annual income (maintenenace)'!M33 -> 0 | L7: ='Annual income (maintenenace)'!N33 -> 0 | M7: ='Annual income (maintenenace)'!O33 -> 0 | ... O7: ='Annual income (maintenenace)'!Q33 -> 0 | Q7: =SUM(D7:O7) -> 67500 | R7: =O7-Q7 -> -67500
B8: 3 | C8: مصروفات الشهر | D8: =January!R26 -> -9925 | E8: =Feb.!T26 -> -30605 | F8: =Mar.!T24 -> -11140 | G8: =Apr.!S18 -> -9080 | H8: ='Annual expenses (combined)'!H36 -> 0 | I8: ='Annual expenses (combined)'!I36 -> 0 | J8: ='Annual expenses (combined)'!J36 -> 0 | K8: ='Annual expenses (combined)'!K36 -> 0 | L8: ='Annual expenses (combined)'!L36 -> 0 | M8: ='Annual expenses (combined)'!M36 -> 0 | N8: ='Annual expenses (combined)'!N36 -> 0 | O8: ='Annual expenses (combined)'!O36 -> 0 | Q8: =SUM(D8:P8) -> -60750 | R8: =O8-Q8 -> 60750
C9: الرصيــــــــــــــــد | D9: =SUM(D6:D8) -> 51346 | E9: =SUM(E6:E8) -> 30241 | F9: =SUM(F6:F8) -> 32301 | G9: =SUM(G6:G8) -> 32721 | H9: =SUM(H6:H8) -> 46521 | I9: =SUM(I6:I8) -> 52521 | J9: =SUM(J6:J8) -> 52521 | K9: =SUM(K6:K8) -> 52521 | ... O9: =SUM(O6:O8) -> 52521 | Q9: =SUM(Q6:Q8) -> 52521 | R9: =O9=Q9 -> TRUE
B11: حســـــــــــــــــــــــــــــــــــــــــــــاب الاسانسير
B13: م | C13: المبلغ | D13: يناير | E13: فبراير | F13: مارس | G13: ابريل | H13: مايو | I13: يونيو | J13: يوليو | K13: اغسطس | L13: سبتمبر | M13: اكتوبر | N13: نوفمبر | O13: ديسمبر | Q13: Check Formula
B14: 1 | C14: فائض مرحل | D14: =January!R30 -> 35180 | E14: =D17 -> 37280 | F14: =E17 -> 37580 | G14: =F17 -> 39180 | H14: =G17 -> 40080 | I14: =H17 -> 39880 | J14: =I17 -> 40780 | K14: =J17 -> 40780 | L14: =K17 -> 40780 | ... O14: =N17 -> 40780 | Q14: =D14 -> 35180
B15: 2 | C15: إيرادات الشهر | D15: ='Annual income ( Elevator)'!F33 -> 2800 | E15: ='Annual income ( Elevator)'!G33 -> 1000 | F15: ='Annual income ( Elevator)'!H33 -> 2300 | G15: ='Annual income ( Elevator)'!I33 -> 1600 | H15: ='Annual income ( Elevator)'!J33 -> 1500 | I15: ='Annual income ( Elevator)'!K33 -> 900 | J15: ='Annual income ( Elevator)'!L33 -> 0 | K15: ='Annual income ( Elevator)'!M33 -> 0 | ... O15: ='Annual income ( Elevator)'!Q33 -> 0 | Q15: =SUM(D15:O15) -> 10100
B16: 3 | C16: مصروفات الشهر | D16: ='Annual expenses (combined)'!D38 -> -700 | E16: ='Annual expenses (combined)'!E38 -> -700 | F16: ='Annual expenses (combined)'!F38 -> -700 | G16: ='Annual expenses (combined)'!G38 -> -700 | H16: ='Annual expenses (combined)'!H38 -> -1700 | I16: ='Annual expenses (combined)'!I38 -> 0 | J16: ='Annual expenses (combined)'!J38 -> 0 | K16: ='Annual expenses (combined)'!K38 -> 0 | ... O16: ='Annual expenses (combined)'!O38 -> 0 | Q16: =SUM(D16:P16) -> -4500
C17: الرصيــــــــــــــــد | D17: =SUM(D14:D16) -> 37280 | E17: =SUM(E14:E16) -> 37580 | F17: =SUM(F14:F16) -> 39180 | G17: =SUM(G14:G16) -> 40080 | H17: =SUM(H14:H16) -> 39880 | I17: =SUM(I14:I16) -> 40780 | J17: =SUM(J14:J16) -> 40780 | K17: =SUM(K14:K16) -> 40780 | ... O17: =SUM(O14:O16) -> 40780 | Q17: =SUM(Q14:Q16) -> 40780 | R17: =O17=Q17 -> TRUE
B19: حســـــــــــــــــــــــــــــــــــــــــــــاب مجمع (الصيانة + الاسانسير)
B21: م | C21: المبلغ | D21: يناير | E21: فبراير | F21: مارس | G21: ابريل | H21: مايو | I21: يونيو | J21: يوليو | K21: اغسطس | L21: سبتمبر | M21: اكتوبر | N21: نوفمبر | O21: ديسمبر | Q21: Check Formula
B22: 1 | C22: فائض مرحل | D22: =D6+D14 -> 80951 | E22: =E6+E14 -> 88626 | F22: =F6+F14 -> 67821 | G22: =G6+G14 -> 71481 | H22: =H6+H14 -> 72801 | I22: =I6+I14 -> 86401 | J22: =J6+J14 -> 93301 | K22: =K6+K14 -> 93301 | ... O22: =O6+O14 -> 93301 | Q22: =D22 -> 80951
B23: 2 | C23: إيرادات الشهر | D23: =D7+D15 -> 18300 | E23: =E7+E15 -> 10500 | F23: =F7+F15 -> 15500 | G23: =G7+G15 -> 11100 | H23: =H7+H15 -> 15300 | I23: =I7+I15 -> 6900 | J23: =J7+J15 -> 0 | K23: =K7+K15 -> 0 | ... O23: =O7+O15 -> 0 | Q23: =SUM(D23:O23) -> 77600
B24: 3 | C24: مصروفات الشهر | D24: =D8+D16 -> -10625 | E24: =E8+E16 -> -31305 | F24: =F8+F16 -> -11840 | G24: =G8+G16 -> -9780 | H24: =H8+H16 -> -1700 | I24: =I8+I16 -> 0 | J24: =J8+J16 -> 0 | K24: =K8+K16 -> 0 | ... O24: =O8+O16 -> 0 | Q24: =SUM(D24:P24) -> -65250
C25: الرصيــــــــــــــــد | D25: =SUM(D22:D24) -> 88626 | E25: =SUM(E22:E24) -> 67821 | F25: =SUM(F22:F24) -> 71481 | G25: =SUM(G22:G24) -> 72801 | H25: =SUM(H22:H24) -> 86401 | I25: =SUM(I22:I24) -> 93301 | J25: =SUM(J22:J24) -> 93301 | K25: =SUM(K22:K24) -> 93301 | ... O25: =SUM(O22:O24) -> 93301 | Q25: =SUM(Q22:Q24) -> 93301 | R25: =O25=Q25 -> TRUE
D27: =D25=January!T35 -> TRUE | E27: =E25=Feb.!T35 -> TRUE | F27: =Mar.!T33=F25 -> TRUE | G27: =G25=Apr.!S35 -> TRUE | H27: =May!S35=H25 -> FALSE | I27: =Jun!S35=I25 -> FALSE | J27: =Jul!S35=J25 -> FALSE | K27: =Aug!S35=K25 -> FALSE | L27: =Sep!S37=L25 -> FALSE | M27: =Oct!S35=M25 -> FALSE | N27: =Nov!S35=N25 -> FALSE | O27: =Dec!S35=O25 -> FALSE | P27: =Jun!Z35=P25 -> TRUE

Sheet YTD Income (Combined)
C3: عمارة 14 بالم الزهراء - الشطر السابع
C4: كشف ايرادات المحمع من يناير الي شهر ديسمبر 2026
C6: م | D6: الاسم | E6: الشقة | F6: يناير | G6: فبراير | H6: مارس | I6: ابريل | J6: مايو | K6: يونيو | L6: يوليو | M6: اغسطس | N6: سبتمبر | O6: اكتوبر | P6: نوفمبر | Q6: ديسمبر | R6: الإجمالي
C7: 1 | D7: مريم اسحاق | E7: A1 | F7: ='Annual Income (Combined)'!F7 -> 500 | G7: ='Annual Income (Combined)'!G7 -> 0 | H7: ='Annual Income (Combined)'!H7 -> 500 | I7: ='Annual Income (Combined)'!I7 -> 500 | J7: ='Annual Income (Combined)'!J7 -> 500 | K7: ='Annual Income (Combined)'!K7 -> 500 | L7: ='Annual Income (Combined)'!L7 -> 0 | M7: ='Annual Income (Combined)'!M7 -> 0 | ... Q7: ='Annual Income (Combined)'!Q7 -> 0 | R7: =SUM(F7:Q7) -> 2500
C8: 2 | D8: وليد مدحت | E8: A2 | F8: ='Annual Income (Combined)'!F8 -> 500 | G8: ='Annual Income (Combined)'!G8 -> 500 | H8: ='Annual Income (Combined)'!H8 -> 500 | I8: ='Annual Income (Combined)'!I8 -> 500 | J8: ='Annual Income (Combined)'!J8 -> 500 | K8: ='Annual Income (Combined)'!K8 -> 500 | L8: ='Annual Income (Combined)'!L8 -> 0 | M8: ='Annual Income (Combined)'!M8 -> 0 | ... Q8: ='Annual Income (Combined)'!Q8 -> 0 | R8: =SUM(F8:Q8) -> 3000
C9: 3 | D9: ناريمان ظريف | E9: B1 | F9: ='Annual Income (Combined)'!F9 -> 0 | G9: ='Annual Income (Combined)'!G9 -> 0 | H9: ='Annual Income (Combined)'!H9 -> 0 | I9: ='Annual Income (Combined)'!I9 -> 0 | J9: ='Annual Income (Combined)'!J9 -> 0 | K9: ='Annual Income (Combined)'!K9 -> 0 | L9: ='Annual Income (Combined)'!L9 -> 0 | M9: ='Annual Income (Combined)'!M9 -> 0 | ... Q9: ='Annual Income (Combined)'!Q9 -> 0 | R9: =SUM(F9:Q9) -> 0
C10: 4 | D10: هند صادق | E10: B2 | F10: ='Annual Income (Combined)'!F10 -> 500 | G10: ='Annual Income (Combined)'!G10 -> 500 | H10: ='Annual Income (Combined)'!H10 -> 500 | I10: ='Annual Income (Combined)'!I10 -> 500 | J10: ='Annual Income (Combined)'!J10 -> 500 | K10: ='Annual Income (Combined)'!K10 -> 500 | L10: ='Annual Income (Combined)'!L10 -> 0 | M10: ='Annual Income (Combined)'!M10 -> 0 | ... Q10: ='Annual Income (Combined)'!Q10 -> 0 | R10: =SUM(F10:Q10) -> 3000
C11: 5 | D11: شريف جداره | E11: A11 | F11: ='Annual Income (Combined)'!F11 -> 600 | G11: ='Annual Income (Combined)'!G11 -> 600 | H11: ='Annual Income (Combined)'!H11 -> 1200 | I11: ='Annual Income (Combined)'!I11 -> 600 | J11: ='Annual Income (Combined)'!J11 -> 600 | K11: ='Annual Income (Combined)'!K11 -> 600 | L11: ='Annual Income (Combined)'!L11 -> 0 | M11: ='Annual Income (Combined)'!M11 -> 0 | ... Q11: ='Annual Income (Combined)'!Q11 -> 0 | R11: =SUM(F11:Q11) -> 4200
C12: 6 | D12: سامح السعيد | E12: A12 | F12: ='Annual Income (Combined)'!F12 -> 600 | G12: ='Annual Income (Combined)'!G12 -> 600 | H12: ='Annual Income (Combined)'!H12 -> 600 | I12: ='Annual Income (Combined)'!I12 -> 600 | J12: ='Annual Income (Combined)'!J12 -> 600 | K12: ='Annual Income (Combined)'!K12 -> 600 | L12: ='Annual Income (Combined)'!L12 -> 0 | M12: ='Annual Income (Combined)'!M12 -> 0 | ... Q12: ='Annual Income (Combined)'!Q12 -> 0 | R12: =SUM(F12:Q12) -> 3600
C13: 7 | D13: احمد يونس | E13: A13 | F13: ='Annual Income (Combined)'!F13 -> 0 | G13: ='Annual Income (Combined)'!G13 -> 0 | H13: ='Annual Income (Combined)'!H13 -> 0 | I13: ='Annual Income (Combined)'!I13 -> 0 | J13: ='Annual Income (Combined)'!J13 -> 4200 | K13: ='Annual Income (Combined)'!K13 -> 0 | L13: ='Annual Income (Combined)'!L13 -> 0 | M13: ='Annual Income (Combined)'!M13 -> 0 | ... Q13: ='Annual Income (Combined)'!Q13 -> 0 | R13: =SUM(F13:Q13) -> 4200
C14: 8 | D14: محمد ابو بكر | E14: B11 | F14: ='Annual Income (Combined)'!F14 -> 300 | G14: ='Annual Income (Combined)'!G14 -> 0 | H14: ='Annual Income (Combined)'!H14 -> 600 | I14: ='Annual Income (Combined)'!I14 -> 300 | J14: ='Annual Income (Combined)'!J14 -> 300 | K14: ='Annual Income (Combined)'!K14 -> 0 | L14: ='Annual Income (Combined)'!L14 -> 0 | M14: ='Annual Income (Combined)'!M14 -> 0 | ... Q14: ='Annual Income (Combined)'!Q14 -> 0 | R14: =SUM(F14:Q14) -> 1500
C15: 9 | D15: خالد خشبه | E15: B12 | F15: ='Annual Income (Combined)'!F15 -> 500 | G15: ='Annual Income (Combined)'!G15 -> 500 | H15: ='Annual Income (Combined)'!H15 -> 500 | I15: ='Annual Income (Combined)'!I15 -> 500 | J15: ='Annual Income (Combined)'!J15 -> 500 | K15: ='Annual Income (Combined)'!K15 -> 0 | L15: ='Annual Income (Combined)'!L15 -> 0 | M15: ='Annual Income (Combined)'!M15 -> 0 | ... Q15: ='Annual Income (Combined)'!Q15 -> 0 | R15: =SUM(F15:Q15) -> 2500
C16: 10 | D16: خالد عبد الصمد | E16: B13 | F16: ='Annual Income (Combined)'!F16 -> 0 | G16: ='Annual Income (Combined)'!G16 -> 0 | H16: ='Annual Income (Combined)'!H16 -> 1200 | I16: ='Annual Income (Combined)'!I16 -> 1200 | J16: ='Annual Income (Combined)'!J16 -> 0 | K16: ='Annual Income (Combined)'!K16 -> 0 | L16: ='Annual Income (Combined)'!L16 -> 0 | M16: ='Annual Income (Combined)'!M16 -> 0 | ... Q16: ='Annual Income (Combined)'!Q16 -> 0 | R16: =SUM(F16:Q16) -> 2400
C17: 11 | D17: أشرف علوي | E17: A21 | F17: ='Annual Income (Combined)'!F17 -> 0 | G17: ='Annual Income (Combined)'!G17 -> 0 | H17: ='Annual Income (Combined)'!H17 -> 2400 | I17: ='Annual Income (Combined)'!I17 -> 0 | J17: ='Annual Income (Combined)'!J17 -> 0 | K17: ='Annual Income (Combined)'!K17 -> 1200 | L17: ='Annual Income (Combined)'!L17 -> 0 | M17: ='Annual Income (Combined)'!M17 -> 0 | ... Q17: ='Annual Income (Combined)'!Q17 -> 0 | R17: =SUM(F17:Q17) -> 3600
C18: 12 | D18: ايهاب محمود | E18: A23 | F18: ='Annual Income (Combined)'!F18 -> 600 | G18: ='Annual Income (Combined)'!G18 -> 600 | H18: ='Annual Income (Combined)'!H18 -> 600 | I18: ='Annual Income (Combined)'!I18 -> 600 | J18: ='Annual Income (Combined)'!J18 -> 600 | K18: ='Annual Income (Combined)'!K18 -> 600 | L18: ='Annual Income (Combined)'!L18 -> 0 | M18: ='Annual Income (Combined)'!M18 -> 0 | ... Q18: ='Annual Income (Combined)'!Q18 -> 0 | R18: =SUM(F18:Q18) -> 3600
... C32: 26 | D32: ساره عادل | E32: B43 | F32: ='Annual Income (Combined)'!F32 -> 0 | G32: ='Annual Income (Combined)'!G32 -> 0 | H32: ='Annual Income (Combined)'!H32 -> 0 | I32: ='Annual Income (Combined)'!I32 -> 1600 | J32: ='Annual Income (Combined)'!J32 -> 400 | K32: ='Annual Income (Combined)'!K32 -> 0 | L32: ='Annual Income (Combined)'!L32 -> 0 | M32: ='Annual Income (Combined)'!M32 -> 0 | ... Q32: ='Annual Income (Combined)'!Q32 -> 0 | R32: =SUM(F32:Q32) -> 2000
C33: الإجـــــــــــــــــــــــــــــــــــــــــــــــــــــــــــــــــــــمالي | F33: =SUM(F7:F32) -> 18300 | G33: =SUM(G7:G32) -> 7500 | H33: =SUM(H7:H32) -> 15500 | I33: =SUM(I7:I32) -> 11100 | J33: =SUM(J7:J32) -> 15300 | K33: =SUM(K7:K32) -> 6900 | L33: =SUM(L7:L32) -> 0 | M33: =SUM(M7:M32) -> 0 | ... R33: =SUM(R7:R32) -> 74600
F35: =F33=January!H33+January!I33 -> TRUE | G35: =G33=Feb.!H33+Feb.!I33 -> TRUE | H35: =H33=Mar.!H33+Mar.!I33 -> TRUE | I35: =I33=Apr.!H35+Apr.!I35 -> TRUE | J35: =May!H35+May!I35=J33 -> TRUE | K35: =+Jun!H35+Jun!I35=K33 -> TRUE | L35: =Jul!H35+Jul!I35='YTD Income (Combined)'!L33 -> TRUE | M35: =Aug!H35+Aug!I35='YTD Income (Combined)'!M33 -> TRUE | N35: =Sep!I35+Sep!H35='YTD Income (Combined)'!N33 -> TRUE | O35: =Oct!H35+Oct!I35='YTD Income (Combined)'!O33 -> TRUE | P35: =Nov!I35+Nov!H35='YTD Income (Combined)'!P33 -> TRUE | Q35: =Dec!H35+Dec!I35='YTD Income (Combined)'!Q33 -> TRUE | R35: =R33=January!H33+January!I33+Feb.!H33+Feb.!I33+Mar.!H33+Mar.!I33+Apr.!H35+Apr.!I35+May!H35+May!I35+Jun!H35+Jun!I35+Jul!H35+Jul!I35+Aug!H35+Aug!I35+Sep!H35+Sep!I35+Oct!H35+Oct!I35+Nov!H35+Nov!I35+Dec!H35+Dec!I35 -> TRUE | S35: =R33='Annual income ( Elevator)'!R33+'Annual income (maintenenace)'!R33 -> TRUE
J37: =SUM(J35:J36) -> 0
I38: =January!H33+January!I33+Feb.!H33+Feb.!I33+Mar.!H33+Mar.!I33+Apr.!H35+Apr.!I35+May!H35+May!I35+Jun!H35+Jun!I35+Jul!H35+Jul!I35+Aug!H35+Aug!I35+Sep!H35+Sep!I35 -> 74600
I39: =I38-R33 -> 0

Sheet Annual expenses (combined)
B3: عمارة 14 بالم الزهراء - الشطر السابع | Q3: الإجمالي
B4: كشف مصروفات 2026
B5: م | C5: بيان | D5: يناير | E5: فبراير | F5: مارس | G5: ابريل | H5: مايو | I5: يونيو | J5: يوليو | K5: اغسطس | L5: سبتمبر | M5: اكتوبر | N5: نوفمبر | O5: ديسمبر
B6: 1 | C6: راتب الحارس | D6: =January!T7 -> -3000 | E6: =Feb.!T7 -> -3000 | Q6: =SUM(D6:P6) -> -6000
B7: 2 | C7: فاتورة مياة | D7: =January!T8 -> -2900 | E7: =Feb.!T8 -> -3255 | Q7: =SUM(D7:P7) -> -6155
B8: 3 | C8: كهرباء | D8: =January!T9 -> -2400 | E8: =Feb.!T9 -> -3000 | Q8: =SUM(D8:P8) -> -5400
B9: 4 | C9: غيار ممسحة | D9: =January!T10 -> -125 | E9: =Feb.!T10 -> -250 | Q9: =SUM(D9:P9) -> -375
B10: 5 | C10: اجرة الجنايني | D10: =January!T11 -> -400 | E10: =Feb.!T11 -> -400 | Q10: =SUM(D10:P10) -> -800
B11: 6 | C11: مستلزمات نظافة | D11: =January!T12 -> -500 | E11: =Feb.!T15 -> -500 | Q11: =SUM(D11:P11) -> -1000
B12: 7 | C12: جركن زيت للاسانسير | D12: =January!T13 -> -600 | Q12: =SUM(D12:P12) -> -600
B13: 8 | C13: مواسير رى الجنينة | Q13: =SUM(D13:P13) -> 0
B14: 9 | C14: مبيد حشري للحديقه الاماميه | Q14: =SUM(D14:P14) -> 0
B15: 10 | C15: دهان السلالم | Q15: =SUM(D15:P15) -> 0
B16: 11 | C16: نقل مخلفات الجنينة | Q16: =SUM(D16:P16) -> 0
B17: 12 | C17: تركيب وفك زينه رمضان | E17: =Feb.!T13 -> -8750 | Q17: =SUM(D17:P17) -> -8750
B18: 13 | C18: شراء لمبات | Q18: =SUM(D18:P18) -> 0
B19: 14 | C19: تصليح موتور المياه | Q19: =SUM(D19:P19) -> 0
B20: 15 | C20: عيدية البواب | Q20: =SUM(D20:P20) -> 0
B21: 16 | C21: لوحة العمارة | Q21: =SUM(D21:P21) -> 0
B22: 17 | C22: شفرات الاسانسير | Q22: =SUM(D22:P22) -> 0
B23: 18 | C23: رخام السلم (صدادات) | Q23: =SUM(D23:P23) -> 0
B24: 19 | C24: فيشر ومصنعيه مواسير | Q24: =SUM(D24:P24) -> 0
B25: 20 | C25: عموله تحويل | Q25: =SUM(D25:P25) -> 0
B26: 21 | C26: جهاز شفرات الاسانسير B ,مروحة اسانسير B | E26: =Feb.!T17 -> -500 | Q26: =SUM(D26:P26) -> -500
B27: 22 | C27: =Oct!R15 -> مبيدات | Q27: =SUM(D27:P27) -> 0
B28: 23 | C28: دفتر ايصالات | Q28: =SUM(D28:P28) -> 0
B29: 24 | C29: تصليح باب الجراج (مقبض) | Q29: =SUM(D29:P29) -> 0
B30: 25 | C30: ترنس | E30: =Feb.!T14 -> -150 | Q30: =SUM(D30:P30) -> -150
B31: 26 | C31: اوتوماتيك للماتور+بالونة موتور + تركيب | E31: =Feb.!T12 -> -10000 | Q31: =SUM(D31:P31) -> -10000
B32: 27 | C32: انتركم + مصنعية | E32: =Feb.!T16 -> -800 | Q32: =SUM(D32:P32) -> -800
B33: 28 | C33: 2 طلمبة باب جراج +مفاتيح +مصنعية | Q33: =SUM(D33:P33) -> 0
B34: 29 | C34: تصليح باب سيكيوريت | Q34: =SUM(D34:P34) -> 0
B35: 30 | C35: =Dec!R15 -> لوازم الجنينة | Q35: =SUM(D35:P35) -> 0
C36: الإجمالي | D36: =SUM(D6:D35) -> -9925 | E36: =SUM(E6:E35) -> -30605 | F36: =SUM(F6:F35) -> 0 | G36: =SUM(G6:G35) -> 0 | H36: =SUM(H6:H35) -> 0 | I36: =SUM(I6:I35) -> 0 | J36: =SUM(J6:J35) -> 0 | K36: =SUM(K6:K35) -> 0 | ... O36: =SUM(O6:O35) -> 0 | Q36: =SUM(Q6:Q35) -> -40530
B38: 20 | C38: الاسانسير | D38: =January!R32 -> -700 | E38: =Feb.!T32 -> -700 | F38: =Mar.!T30 -> -700 | G38: =Apr.!S31 -> -700 | H38: =May!S31 -> -1700 | I38: =Jun!S31 -> 0 | J38: =Jul!S31 -> 0 | K38: =Aug!S31 -> 0 | L38: =Sep!S33 -> 0 | M38: =Oct!S31 -> 0 | N38: =Nov!S31 -> 0 | O38: =Dec!S31 -> 0 | Q38: =SUM(D38:O38) -> -4500
C40: الإجمالي | D40: =SUM(D36:D38) -> -10625 | E40: =SUM(E36:E38) -> -31305 | F40: =SUM(F36:F38) -> -700 | G40: =SUM(G36:G38) -> -700 | H40: =SUM(H36:H38) -> -1700 | I40: =SUM(I36:I38) -> 0 | J40: =SUM(J36:J38) -> 0 | K40: =SUM(K36:K38) -> 0 | ... O40: =SUM(O36:O38) -> 0 | Q40: =SUM(Q36:Q38) -> -45030 | R40: =Q40='Summary Sheet'!Q24 -> FALSE
E42: =E40-Feb.!T32-Feb.!T26 -> 0

Sheet YTD expense Analysis 
B3: عمارة 14 بالم الزهراء - الشطر السابع | Q3: Total | R3: Percentage
B4: كشف مصروفات شهر ديسمبر 2024
AE5: بيان | AF5: total | AI5: بيان | AJ5: total | AK5: %
AI6: Total | AJ6: =SUM(AJ1:AJ4) -> 0 | AK6: =SUM(AK1:AK2) -> 0
AI7: راتب الحارس | AJ7: ='Annual expenses (combined)'!Q6 -> -6000 | AK7: =AJ7/$AJ$37 -> 0.1332445
AI8: فاتورة مياة | AJ8: ='Annual expenses (combined)'!Q7 -> -6155 | AK8: =AJ8/$AJ$37 -> 0.13668665
AI9: كهرباء | AJ9: ='Annual expenses (combined)'!Q8 -> -5400 | AK9: =AJ9/$AJ$37 -> 0.11992005
AI10: غيار ممسحة | AJ10: ='Annual expenses (combined)'!Q9 -> -375 | AK10: =AJ10/$AJ$37 -> 0.0083277815
AI11: اجرة الجنايني | AJ11: ='Annual expenses (combined)'!Q10 -> -800 | AK11: =AJ11/$AJ$37 -> 0.017765934
AI12: مستلزمات نظافة | AJ12: ='Annual expenses (combined)'!Q11 -> -1000 | AK12: =AJ12/$AJ$37 -> 0.022207417
AI13: جركن زيت للاسانسير | AJ13: ='Annual expenses (combined)'!Q12 -> -600 | AK13: =AJ13/$AJ$37 -> 0.01332445
AI14: مواسير رى الجنينة | AJ14: ='Annual expenses (combined)'!Q13 -> 0 | AK14: =AJ14/$AJ$37 -> 0
AI15: مبيد حشري للحديقه الاماميه | AJ15: ='Annual expenses (combined)'!Q14 -> 0 | AK15: =AJ15/$AJ$37 -> 0
AI16: دهان السلالم | AJ16: ='Annual expenses (combined)'!Q15 -> 0 | AK16: =AJ16/$AJ$37 -> 0
AI17: نقل مخلفات الجنينة | AJ17: ='Annual expenses (combined)'!Q16 -> 0 | AK17: =AJ17/$AJ$37 -> 0
AI18: تركيب وفك زينه رمضان | AJ18: ='Annual expenses (combined)'!Q17 -> -8750 | AK18: =AJ18/$AJ$37 -> 0.1943149
AI19: شراء لمبات | AJ19: ='Annual expenses (combined)'!Q18 -> 0 | AK19: =AJ19/$AJ$37 -> 0
B20: م | C20: بيان | D20: January | E20: February | F20: March | G20: April | H20: May | I20: June | J20: July | K20: August | L20: September | M20: October | N20: November | O20: December | AE20: مرتب البواب | AF20: -24500 | AG20: =AF20/$AF$52 -> 0.30719077 | AI20: تصليح موتور المياه | AJ20: ='Annual expenses (combined)'!Q19 -> 0 | AK20: =AJ20/$AJ$37 -> 0
B21: 1 | C21: راتب الحارس | D21: -2000 | E21: -2000 | F21: -2000 | G21: -2000 | H21: -2000 | I21: -2000 | J21: -2000 | K21: -2000 | L21: -2000 | M21: -2000 | N21: -2000 | O21: -2500 | Q21: =SUM(D21:P21) -> -24500 | R21: =Q21/$Q$52 -> 0.30719077 | AE21: فاتورة مياة | AF21: -20675 | AG21: =AF21/$AF$52 -> 0.2592314 | AI21: عيدية البواب | AJ21: ='Annual expenses (combined)'!Q20 -> 0 | AK21: =AJ21/$AJ$37 -> 0
B22: 2 | C22: فاتورة مياة | D22: -2200 | E22: -2200 | F22: -1100 | G22: -1100 | H22: -1250 | I22: -1300 | J22: -1725 | K22: -1720 | L22: -1850 | M22: -1830 | N22: -2200 | O22: -2200 | Q22: =SUM(D22:P22) -> -20675 | R22: =Q22/$Q$52 -> 0.2592314 | AE22: كهرباء | AF22: -10700 | AG22: =AF22/$AF$52 -> 0.13416087 | AI22: لوحة العمارة | AJ22: ='Annual expenses (combined)'!Q21 -> 0 | AK22: =AJ22/$AJ$37 -> 0
B23: 3 | C23: كهرباء | D23: 0 | E23: -1200 | F23: -1000 | G23: -1000 | H23: -1000 | I23: -1000 | J23: -1000 | L23: -1000 | M23: -1000 | N23: -1500 | O23: -1000 | Q23: =SUM(D23:P23) -> -10700 | R23: =Q23/$Q$52 -> 0.13416087 | AE23: اجرة الجنايني | AF23: -3600 | AG23: =AF23/$AF$52 -> 0.045138236 | AI23: شفرات الاسانسير | AJ23: ='Annual expenses (combined)'!Q22 -> 0 | AK23: =AJ23/$AJ$37 -> 0
B24: 4 | C24: اجرة الجنايني | D24: -300 | E24: -300 | F24: -300 | G24: -300 | H24: -300 | I24: -300 | J24: -300 | K24: -300 | L24: -300 | M24: -300 | N24: -300 | O24: -300 | Q24: =SUM(D24:P24) -> -3600 | R24: =Q24/$Q$52 -> 0.045138236 | AE24: مستلزمات نظافة | AF24: -3760 | AG24: =AF24/$AF$52 -> 0.04714438 | AI24: رخام السلم (صدادات) | AJ24: ='Annual expenses (combined)'!Q23 -> 0 | AK24: =AJ24/$AJ$37 -> 0
B25: 5 | C25: مستلزمات نظافة | D25: -300 | E25: -600 | F25: -300 | G25: 0 | H25: -350 | I25: -360 | J25: -400 | K25: -400 | L25: -300 | M25: 0 | N25: -400 | O25: -350 | Q25: =SUM(D25:P25) -> -3760 | R25: =Q25/$Q$52 -> 0.04714438 | AE25: تصليح موتور المياه شراء عدد 2 بالونه تيوبليس | AF25: -3800 | AG25: =AF25/$AF$52 -> 0.047645916 | AI25: فيشر ومصنعيه مواسير | AJ25: ='Annual expenses (combined)'!Q24 -> 0 | AK25: =AJ25/$AJ$37 -> 0
B26: 6 | C26: تصليح موتور المياه شراء عدد 2 بالونه تيوبليس | D26: 0 | E26: 0 | F26: 0 | G26: -1500 | H26: 0 | I26: -2300 | J26: 0 | K26: 0 | L26: 0 | M26: 0 | N26: 0 | O26: 0 | Q26: =SUM(D26:P26) -> -3800 | R26: =Q26/$Q$52 -> 0.047645916 | AE26: غيار ممسحة | AF26: -2100 | AG26: =AF26/$AF$52 -> 0.026330638 | AI26: عموله تحويل | AJ26: ='Annual expenses (combined)'!Q25 -> 0 | AK26: =AJ26/$AJ$37 -> 0
B27: 7 | C27: غيار ممسحة | D27: -200 | E27: -100 | F27: -200 | G27: -200 | H27: -200 | I27: -100 | J27: -200 | K27: -200 | L27: -100 | M27: -200 | N27: -200 | O27: -200 | Q27: =SUM(D27:P27) -> -2100 | R27: =Q27/$Q$52 -> 0.026330638 | AE27: عيديه صلاح | AF27: -2000 | AG27: =AF27/$AF$52 -> 0.025076798 | AI27: جهاز شفرات الاسانسير B ,مروحة اسانسير B | AJ27: ='Annual expenses (combined)'!Q26 -> -500 | AK27: =AJ27/$AJ$37 -> 0.011103709
B28: 8 | C28: عيديه صلاح | D28: 0 | E28: 0 | F28: 0 | G28: -1000 | H28: 0 | I28: -1000 | J28: 0 | K28: 0 | L28: 0 | M28: 0 | N28: 0 | O28: 0 | Q28: =SUM(D28:P28) -> -2000 | R28: =Q28/$Q$52 -> 0.025076798 | AE28: تصليح بوابه الجراج | AF28: -1500 | AG28: =AF28/$AF$52 -> 0.018807598 | AI28: مبيدات | AJ28: ='Annual expenses (combined)'!Q27 -> 0 | AK28: =AJ28/$AJ$37 -> 0
B29: 9 | C29: تصليح بوابه الجراج | D29: -400 | E29: -500 | F29: 0 | G29: -300 | H29: 0 | I29: 0 | J29: 0 | K29: 0 | L29: 0 | M29: -300 | N29: 0 | O29: 0 | Q29: =SUM(D29:P29) -> -1500 | R29: =Q29/$Q$52 -> 0.018807598 | AE29: شراء عدد 2 سله قمامه | AF29: -1600 | AG29: =AF29/$AF$52 -> 0.020061438 | AI29: دفتر ايصالات | AJ29: ='Annual expenses (combined)'!Q28 -> 0 | AK29: =AJ29/$AJ$37 -> 0
AI30: تصليح باب الجراج (مقبض) | AJ30: ='Annual expenses (combined)'!Q29 -> 0 | AK30: =AJ30/$AJ$37 -> 0
AI31: لمبات اسانسير A | AJ31: ='Annual expenses (combined)'!Q30 -> -150 | AK31: =AJ31/$AJ$37 -> 0.0033311126
AI32: لمبات ومصنعية للسور الخلفي | AJ32: ='Annual expenses (combined)'!Q31 -> -10000 | AK32: =AJ32/$AJ$37 -> 0.22207417
AI33: انتركم + مصنعية | AJ33: ='Annual expenses (combined)'!Q32 -> -800 | AK33: =AJ33/$AJ$37 -> 0.017765934
AI34: 2 طلمبة باب جراج +مفاتيح +مصنعية | AJ34: ='Annual expenses (combined)'!Q33 -> 0 | AK34: =AJ34/$AJ$37 -> 0
AI35: تصليح باب سيكيوريت | AJ35: ='Annual expenses (combined)'!Q34 -> 0 | AK35: =AJ35/$AJ$37 -> 0
AI36: الاسانسير | AJ36: ='Annual expenses (combined)'!Q38 -> -4500
B37: 10 | C37: شراء عدد 2 سله قمامه | D37: 0 | E37: 0 | F37: 0 | G37: 0 | H37: -1600 | I37: 0 | J37: 0 | K37: 0 | L37: 0 | M37: 0 | N37: 0 | O37: 0 | Q37: =SUM(D37:P37) -> -1600 | R37: =Q37/$Q$52 -> 0.020061438 | AJ37: =SUM(AJ7:AJ36) -> -45030 | AK37: =AJ37/$AJ$37 -> 1
B38: 11 | C38: تصليح انتركم | D38: 0 | E38: 0 | F38: -350 | G38: 0 | H38: 0 | I38: 0 | J38: 0 | K38: 0 | L38: 0 | M38: 0 | N38: 0 | O38: -400 | Q38: =SUM(D38:P38) -> -750 | R38: =Q38/$Q$52 -> 0.0094037991 | AE38: تصليح انتركم | AF38: -750 | AG38: =AF38/$AF$52 -> 0.0094037991
B39: 12 | C39: شراء 30 متر خرطوم لزوم الحديقه | D39: 0 | E39: 0 | F39: 0 | G39: 0 | H39: 0 | I39: 0 | J39: -1000 | K39: 0 | L39: 0 | M39: 0 | N39: 0 | O39: 0 | Q39: =SUM(D39:P39) -> -1000 | R39: =Q39/$Q$52 -> 0.012538399 | AE39: شراء 30 متر خرطوم لزوم الحديقه | AF39: -1000 | AG39: =AF39/$AF$52 -> 0.012538399 | AJ39: =AJ37-'Annual expenses (combined)'!Q40 -> 0
B40: 13 | C40: تركيب زينه رمضان 2024 | D40: 0 | E40: 0 | F40: -650 | G40: 0 | H40: 0 | I40: 0 | J40: 0 | K40: 0 | L40: 0 | M40: 0 | N40: 0 | O40: 0 | Q40: =SUM(D40:P40) -> -650 | R40: =Q40/$Q$52 -> 0.0081499593 | AE40: تركيب زينه رمضان 2024 | AF40: -650 | AG40: =AF40/$AF$52 -> 0.0081499593 | AJ40: =AJ37='Summary Sheet'!Q24 -> FALSE
B41: 14 | C41: نظافه الخزانات | D41: 0 | E41: 0 | F41: 0 | G41: 0 | H41: 0 | I41: 0 | J41: 0 | K41: -500 | L41: 0 | M41: 0 | N41: 0 | O41: 0 | Q41: =SUM(D41:P41) -> -500 | R41: =Q41/$Q$52 -> 0.0062691994 | AE41: نظافه الخزانات | AF41: -500 | AG41: =AF41/$AF$52 -> 0.0062691994
B42: 15 | C42: =#REF! -> #REF! | D42: 0 | E42: 0 | F42: -400 | G42: 0 | H42: 0 | Q42: =SUM(D42:P42) -> -400 | R42: =Q42/$Q$52 -> 0.0050153595 | AE42: شراء كومبوست للحديقه الاماميه | AF42: -400 | AG42: =AF42/$AF$52 -> 0.0050153595
...

Sheet January
B1: -1
C3: عمارة 14 بالم الزهراء - الشطر السابع | R3: عمارة 14 بالم الزهراء - الشطر السابع
C4: كشف ايرادات ومصروفات شهر يناير 2026 | R4: كشف مصروفات شهر يناير 2026
C6: م | D6: الاسم | E6: الشقة | F6: ايرادات الشهر الجاري | G6: ايرادات الأسانسير | H6: مدفوع صيانه | I6: مدفوع اسانسير | K6: الصيانة مستحقة سابقا | L6: م. اسانسير مستحقة سابقا | N6: اجمالي الصيانة المستحقة | O6: اجمالي م. اسانسير المستحقة | R6: م | S6: بيان | T6: المبلغ | U6: المستند
C7: 1 | D7: مريم اسحاق | E7: A1 | F7: -500 | H7: 500 | K7: 0 | L7: 0 | N7: =F7+H7+K7 -> 0 | O7: =G7+I7+L7 -> 0 | R7: 1 | S7: راتب الحارس | T7: -3000 | U7: إيصال
C8: 2 | D8: وليد مدحت | E8: A2 | F8: -500 | H8: 500 | K8: 0 | L8: 0 | N8: =F8+H8+K8 -> 0 | O8: =G8+I8+L8 -> 0 | R8: 2 | S8: فاتورة مياة | T8: -2900
C9: 3 | D9: ناريمان ظريف | E9: B1 | F9: -300 | K9: -5400 | L9: 0 | N9: =F9+H9+K9 -> -5700 | O9: =G9+I9+L9 -> 0 | R9: 3 | S9: كهرباء | T9: -2400 | U9: إيصال
C10: 4 | D10: هند صادق | E10: B2 | F10: -500 | H10: 500 | K10: 0 | L10: 0 | N10: =F10+H10+K10 -> 0 | O10: =G10+I10+L10 -> 0 | R10: 4 | S10: غيار ممسحة | T10: -125
C11: 5 | D11: شريف جداره | E11: A11 | F11: -500 | G11: -100 | H11: 500 | I11: 100 | K11: 0 | L11: 0 | N11: =F11+H11+K11 -> 0 | O11: =G11+I11+L11 -> 0 | R11: 5 | S11: اجرة الجنايني | T11: -400 | U11: فاتورة
C12: 6 | D12: سامح السعيد | E12: A12 | F12: -500 | G12: -100 | H12: 500 | I12: 100 | K12: 0 | L12: 0 | N12: =F12+H12+K12 -> 0 | O12: =G12+I12+L12 -> 0 | R12: 6 | S12: مستلزمات نظافة | T12: -500 | U12: إيصال
C13: 7 | D13: احمد يونس | E13: A13 | F13: -300 | K13: -2700 | L13: 0 | N13: =F13+H13+K13 -> -3000 | O13: =G13+I13+L13 -> 0 | R13: 7 | S13: جركن زيت للاسانسير | T13: -600 | U13: إيصال
C14: 8 | D14: محمد ابو بكر | E14: B11 | F14: -300 | H14: 300 | K14: 0 | L14: 0 | N14: =F14+H14+K14 -> 0 | O14: =G14+I14+L14 -> 0 | R14: 8 | U14: فاتورة
C15: 9 | D15: خالد خشبه | E15: B12 | F15: -500 | H15: 500 | K15: 0 | L15: 0 | N15: =F15+H15+K15 -> 0 | O15: =G15+I15+L15 -> 0 | R15: 9
C16: 10 | D16: خالد عبد الصمد | E16: B13 | F16: -500 | G16: -100 | K16: 0 | L16: 0 | N16: =F16+H16+K16 -> -500 | O16: =G16+I16+L16 -> -100 | R16: 10
C17: 11 | D17: أشرف علوي | E17: A21 | F17: -500 | G17: -100 | K17: -500 | L17: -100 | N17: =F17+H17+K17 -> -1000 | O17: =G17+I17+L17 -> -200 | S17: الإجمالي | T17: =SUM(T7:T16) -> -9925
C18: 12 | D18: ايهاب محمود | E18: A23 | F18: -500 | G18: -100 | H18: 500 | I18: 100 | K18: 0 | L18: 0 | N18: =F18+H18+K18 -> 0 | O18: =G18+I18+L18 -> 0
C19: 13 | D19: أسامه حسين | E19: B21 | F19: -300 | G19: -100 | H19: 3000 | I19: 1000 | K19: 0 | L19: 0 | N19: =F19+H19+K19 -> 2700 | O19: =G19+I19+L19 -> 900
C20: 14 | D20: مي اسامة | E20: B22 | F20: -300 | G20: -100 | H20: 300 | I20: 100 | K20: 0 | L20: 0 | N20: =F20+H20+K20 -> 0 | O20: =G20+I20+L20 -> 0
C21: 15 | D21: محمد هلال | E21: B23 | F21: -500 | G21: -100 | K21: 0 | L21: -1500 | N21: =F21+H21+K21 -> -500 | O21: =G21+I21+L21 -> -1600 | R21: حســـــــــــــــــــــــــــــــــــــــــــــاب ختامـــــــــــي
C22: 16 | D22: وجدي محروس | E22: A31 | F22: -500 | G22: -100 | K22: 0 | L22: 0 | N22: =F22+H22+K22 -> -500 | O22: =G22+I22+L22 -> -100
C23: 17 | D23: عمرو عبدالرازق | E23: A32 | F23: -500 | G23: -100 | H23: 500 | I23: 100 | K23: 0 | L23: 0 | N23: =F23+H23+K23 -> 0 | O23: =G23+I23+L23 -> 0 | R23: المبلغ | T23: م
C24: 18 | D24: مدام اميرة | E24: A33 | F24: -300 | K24: 0 | L24: 0 | N24: =F24+H24+K24 -> -300 | O24: =G24+I24+L24 -> 0 | R24: 45771 | S24: فائض مرحل | T24: 1
C25: 19 | D25: ابراهيم محمد | E25: B31 | F25: -500 | G25: -100 | H25: 500 | I25: 100 | K25: 0 | L25: 0 | N25: =F25+H25+K25 -> 0 | O25: =G25+I25+L25 -> 0 | R25: =H33 -> 15500 | S25: إيرادات شهر يناير 2026 | T25: 2
C26: 20 | D26: مصطفى عبد الصبور | E26: B32 | F26: -300 | G26: -100 | H26: 500 | I26: 100 | K26: -300 | L26: -400 | N26: =F26+H26+K26 -> -100 | O26: =G26+I26+L26 -> -400 | R26: =T17 -> -9925 | S26: مصروفات شهر يناير 2026 | T26: 3
C27: 21 | D27: هناء سلامه | E27: B33 | F27: -500 | G27: -100 | H27: 500 | I27: 100 | K27: 0 | L27: 0 | N27: =F27+H27+K27 -> 0 | O27: =G27+I27+L27 -> 0 | R27: =SUM(R24:R26) -> 51346 | T27: الإجمالي
C28: 22 | D28: علي محمد نور الدين | E28: A41 | F28: -500 | G28: -100 | H28: 500 | I28: 100 | K28: 0 | L28: 0 | N28: =F28+H28+K28 -> 0 | O28: =G28+I28+L28 -> 0
C29: 23 | D29: محمد شاكر | E29: A43 | F29: -500 | G29: -100 | H29: 4900 | I29: 700 | K29: -4400 | L29: -600 | N29: =F29+H29+K29 -> 0 | O29: =G29+I29+L29 -> 0 | R29: المبلغ | S29: بيان الاسانسير | T29: م
C30: 24 | D30: محمد السيسي | E30: B41 | F30: -500 | G30: -100 | H30: 500 | I30: 100 | K30: 0 | L30: 0 | N30: =F30+H30+K30 -> 0 | O30: =G30+I30+L30 -> 0 | R30: 35180 | S30: فائض مرحل | T30: 1
C31: 25 | D31: حسام رياض | E31: B42 | F31: -500 | G31: -100 | H31: 500 | I31: 100 | K31: 0 | L31: 0 | N31: =F31+H31+K31 -> 0 | O31: =G31+I31+L31 -> 0 | R31: =I33 -> 2800 | S31: إيرادات الشهر الجارى | T31: 2
C32: 26 | D32: ساره عادل | E32: B43 | F32: -300 | G32: -100 | K32: 0 | L32: 0 | N32: =F32+H32+K32 -> -300 | O32: =G32+I32+L32 -> -100 | R32: =-500-200 -> -700 | S32: مصروفات الشهر الجارى | T32: 3
C33: الإجـــــــــــــــــــــــــــــــــــــــــــــــــــــــــــــــــــــمالي | F33: =SUM(F7:F32) -> -11400 | G33: =SUM(G7:G32) -> -1800 | H33: =SUM(H7:H32) -> 15500 | I33: =SUM(I7:I32) -> 2800 | K33: =SUM(K7:K32) -> -13300 | L33: =SUM(L7:L32) -> -2600 | N33: =SUM(N7:N32) -> -9200 | O33: =SUM(O7:O32) -> -1600 | R33: =SUM(R30:R32) -> 37280 | S33: الإجمالي
H35: =H33-'Annual income (maintenenace)'!F33 -> 0 | L35: =3600/600 -> 6 | R35: الإجمالي (صيانة + اسانسير) | T35: =R33+R27 -> 88626
H36: =H33-'Annual income (maintenenace)'!H35 -> 15500 | L36: =600*11 -> 6600
H37: =5500+800 -> 6300 | I37: =-H36 -> -15500
H38: -3000
K39: =K33+F33+H33 -> -9200 | L39: =L33+G33+I33 -> -1600
H40: 800 | K40: =N33-K33 -> 4100 | L40: =O33-L33 -> 1000
S41: الصندوق | T41: المبلغ
S42: رصيد متوفر مع ا/ إيهاب مهدي | T42: =62978+500+600+600+4000+500+600+400+300+600+5600+600+600+500+600 -> 78978
Q43: =T45-H33-I33 -> 70326 | S43: رصيد متوفر مع ا/ إبراهيم محمد | T43: =17973+500+600+600+600+R26+R32 -> 9648
...

Sheet Feb.
B1: -1
C3: عمارة 14 بالم الزهراء - الشطر السابع | R3: عمارة 14 بالم الزهراء - الشطر السابع
C4: كشف ايرادات ومصروفات شهر فبراير 2026 | R4: كشف مصروفات شهر فبراير 2026
C6: م | D6: الاسم | E6: الشقة | F6: ايرادات الشهر الجاري | G6: ايرادات الأسانسير | H6: مدفوع صيانه | I6: مدفوع اسانسير | K6: الصيانة مستحقة سابقا | L6: م. اسانسير مستحقة سابقا | N6: اجمالي الصيانة المستحقة | O6: اجمالي م. اسانسير المستحقة | R6: م | S6: بيان | T6: المبلغ | U6: المستند
C7: 1 | D7: مريم اسحاق | E7: A1 | F7: -500 | K7: 0 | L7: 0 | N7: =F7+H7+K7 -> -500 | O7: =G7+I7+L7 -> 0 | P7: =January!N7 -> 0 | R7: 1 | S7: راتب الحارس | T7: -3000 | U7: إيصال
C8: 2 | D8: وليد مدحت | E8: A2 | F8: -500 | H8: 500 | K8: 0 | L8: 0 | N8: =F8+H8+K8 -> 0 | O8: =G8+I8+L8 -> 0 | P8: =January!N8 -> 0 | R8: 2 | S8: فاتورة مياة شهر فبراير | T8: -3255
C9: 3 | D9: ناريمان ظريف | E9: B1 | F9: -300 | K9: -5700 | L9: 0 | N9: =F9+H9+K9 -> -6000 | O9: =G9+I9+L9 -> 0 | P9: =January!N9 -> -5700 | R9: 3 | S9: كهرباء | T9: -3000 | U9: إيصال
C10: 4 | D10: هند صادق | E10: B2 | F10: -500 | H10: 500 | K10: 0 | L10: 0 | N10: =F10+H10+K10 -> 0 | O10: =G10+I10+L10 -> 0 | P10: =January!N10 -> 0 | R10: 4 | S10: غيار ممسحة | T10: -250
C11: 5 | D11: شريف جداره | E11: A11 | F11: -500 | G11: -100 | H11: 500 | I11: 100 | K11: 0 | L11: 0 | N11: =F11+H11+K11 -> 0 | O11: =G11+I11+L11 -> 0 | P11: =January!N11 -> 0 | R11: 5 | S11: اجرة الجنايني | T11: -400 | U11: فاتورة
C12: 6 | D12: سامح السعيد | E12: A12 | F12: -500 | G12: -100 | H12: 500 | I12: 100 | K12: 0 | L12: 0 | N12: =F12+H12+K12 -> 0 | O12: =G12+I12+L12 -> 0 | P12: =January!N12 -> 0 | R12: 6 | S12: اوتوماتيك للماتور+بالونة موتور + تركيب | T12: =-5300-4700 -> -10000 | U12: إيصال
C13: 7 | D13: احمد يونس | E13: A13 | F13: -300 | K13: -3000 | L13: 0 | N13: =F13+H13+K13 -> -3300 | O13: =G13+I13+L13 -> 0 | P13: =January!N13 -> -3000 | R13: 7 | S13: زينه رمضان | T13: -8750 | U13: إيصال
C14: 8 | D14: محمد ابو بكر | E14: B11 | F14: -300 | K14: 0 | L14: 0 | N14: =F14+H14+K14 -> -300 | O14: =G14+I14+L14 -> 0 | P14: =January!N14 -> 0 | R14: 8 | S14: ترنس | T14: -150 | U14: إيصال
C15: 9 | D15: خالد خشبه | E15: B12 | F15: -500 | H15: 500 | K15: 0 | L15: 0 | N15: =F15+H15+K15 -> 0 | O15: =G15+I15+L15 -> 0 | P15: =January!N15 -> 0 | R15: 9 | S15: منظفات | T15: -500 | U15: إيصال
C16: 10 | D16: خالد عبد الصمد | E16: B13 | F16: -500 | G16: -100 | K16: -500 | L16: -100 | N16: =F16+H16+K16 -> -1000 | O16: =G16+I16+L16 -> -200 | P16: =January!N16 -> -500 | R16: 10 | S16: تصليح انتركم | T16: -800 | U16: إيصال
C17: 11 | D17: أشرف علوي | E17: A21 | F17: -500 | G17: -100 | K17: -1000 | L17: -200 | N17: =F17+H17+K17 -> -1500 | O17: =G17+I17+L17 -> -300 | P17: =January!N17 -> -1000 | R17: 11 | S17: شفرات اسانسير | T17: -500
C18: 12 | D18: ايهاب محمود | E18: A23 | F18: -500 | G18: -100 | H18: 500 | I18: 100 | K18: 0 | L18: 0 | N18: =F18+H18+K18 -> 0 | O18: =G18+I18+L18 -> 0 | P18: =January!N18 -> 0 | S18: الإجمالي | T18: =SUM(T7:T17) -> -30605
C19: 13 | D19: أسامه حسين | E19: B21 | F19: -500 | G19: -100 | K19: 2700 | L19: 900 | N19: =F19+H19+K19 -> 2200 | O19: =G19+I19+L19 -> 800 | P19: =January!N19 -> 2700
C20: 14 | D20: مي اسامة | E20: B22 | F20: -500 | G20: -100 | K20: 0 | L20: 0 | N20: =F20+H20+K20 -> -500 | O20: =G20+I20+L20 -> -100 | P20: =January!N20 -> 0
C21: 15 | D21: محمد هلال | E21: B23 | F21: -500 | G21: -100 | K21: -500 | L21: -1600 | N21: =F21+H21+K21 -> -1000 | O21: =G21+I21+L21 -> -1700 | P21: =January!N21 -> -500 | R21: حســـــــــــــــــــــــــــــــــــــــــــــاب ختامـــــــــــي
C22: 16 | D22: وجدي محروس | E22: A31 | F22: -500 | G22: -100 | K22: -500 | L22: -100 | N22: =F22+H22+K22 -> -1000 | O22: =G22+I22+L22 -> -200 | P22: =January!N22 -> -500
C23: 17 | D23: عمرو عبدالرازق | E23: A32 | F23: -500 | G23: -100 | K23: 0 | L23: 0 | N23: =F23+H23+K23 -> -500 | O23: =G23+I23+L23 -> -100 | P23: =January!N23 -> 0 | R23: م | T23: المبلغ
C24: 18 | D24: مدام اميرة | E24: A33 | F24: -300 | K24: -300 | L24: 0 | N24: =F24+H24+K24 -> -600 | O24: =G24+I24+L24 -> 0 | P24: =January!N24 -> -300 | R24: 1 | S24: فائض مرحل | T24: =January!R27 -> 51346
C25: 19 | D25: ابراهيم محمد | E25: B31 | F25: -500 | G25: -100 | H25: 500 | I25: 100 | K25: 0 | L25: 0 | N25: =F25+H25+K25 -> 0 | O25: =G25+I25+L25 -> 0 | P25: =January!N25 -> 0 | R25: 2 | S25: إيرادات الشهر الجارى | T25: =H33+3000 -> 9500
C26: 20 | D26: مصطفى عبد الصبور | E26: B32 | F26: -500 | G26: -100 | H26: 500 | I26: 100 | K26: -100 | L26: -400 | N26: =F26+H26+K26 -> -100 | O26: =G26+I26+L26 -> -400 | P26: =January!N26 -> -100 | R26: 3 | S26: مصروفات الشهر الجارى | T26: =T18 -> -30605
C27: 21 | D27: هناء سلامه | E27: B33 | F27: -500 | G27: -100 | H27: 1000 | I27: 200 | K27: 0 | L27: 0 | N27: =F27+H27+K27 -> 500 | O27: =G27+I27+L27 -> 100 | P27: =January!N27 -> 0 | R27: الإجمالي | T27: =SUM(T24:T26) -> 30241
C28: 22 | D28: علي محمد نور الدين | E28: A41 | F28: -500 | G28: -100 | H28: 500 | I28: 100 | K28: 0 | L28: 0 | N28: =F28+H28+K28 -> 0 | O28: =G28+I28+L28 -> 0 | P28: =January!N28 -> 0
C29: 23 | D29: محمد شاكر | E29: A43 | F29: -500 | G29: -100 | H29: 500 | I29: 100 | K29: 0 | L29: 0 | N29: =F29+H29+K29 -> 0 | O29: =G29+I29+L29 -> 0 | P29: =January!N29 -> 0 | R29: م | S29: بيان الاسانسير | T29: المبلغ
C30: 24 | D30: محمد السيسي | E30: B41 | F30: -500 | G30: -100 | K30: 0 | L30: 0 | N30: =F30+H30+K30 -> -500 | O30: =G30+I30+L30 -> -100 | P30: =January!N30 -> 0 | R30: 1 | S30: فائض مرحل | T30: =January!R33 -> 37280
C31: 25 | D31: حسام رياض | E31: B42 | F31: -500 | G31: -100 | H31: 500 | I31: 100 | K31: 0 | L31: 0 | N31: =F31+H31+K31 -> 0 | O31: =G31+I31+L31 -> 0 | P31: =January!N31 -> 0 | R31: 2 | S31: إيرادات الشهر الجارى | T31: =I33 -> 1000
C32: 26 | D32: ساره عادل | E32: B43 | F32: -300 | G32: -100 | K32: -300 | L32: -100 | N32: =F32+H32+K32 -> -600 | O32: =G32+I32+L32 -> -200 | P32: =January!N32 -> -300 | R32: 3 | S32: مصروفات الشهر الجارى | T32: =-200-500 -> -700
C33: الإجـــــــــــــــــــــــــــــــــــــــــــــــــــــــــــــــــــــمالي | F33: =SUM(F7:F32) -> -12000 | G33: =SUM(G7:G32) -> -1800 | H33: =SUM(H7:H32) -> 6500 | I33: =SUM(I7:I32) -> 1000 | K33: =SUM(K7:K32) -> -9200 | L33: =SUM(L7:L32) -> -1600 | N33: =SUM(N7:N32) -> -14700 | O33: =SUM(O7:O32) -> -2400 | R33: الإجمالي | S33: الإجمالي | T33: =SUM(T30:T32) -> 37580
N35: =N33-K33 -> -5500 | R35: =January!R35 -> الإجمالي (صيانة + اسانسير) | T35: =T33+T27 -> 67821
H36: =H33+I33-3600 -> 3900 | N36: =N33-K33 -> -5500
R39: الصندوق | S39: المبلغ
R40: رصيد متوفر مع ا/ إيهاب مهدي | S40: =January!T42+600+600+600+600+500+500-30000+600 -> 52978 | T40: 78900 | U40: =T40-S40 -> 25922
R41: رصيد متوفر مع ا/ إبراهيم محمد | S41: =January!T43+500+600+2000+1000+600+600+30000+T26+T32+1200 -> 14843 | U41: -30000
R43: الإجمالي | S43: =S40+S41 -> 67821
R45: الفــــرق | S45: =S43-T35 -> 0

Sheet Mar.
B1: -1
C3: عمارة 14 بالم الزهراء - الشطر السابع | R3: عمارة 14 بالم الزهراء - الشطر السابع
C4: كشف ايرادات ومصروفات شهر مارس 2026 | R4: كشف مصروفات شهر مارس 2026
C6: م | D6: الاسم | E6: الشقة | F6: ايرادات الشهر الجاري | G6: ايرادات الأسانسير | H6: مدفوع صيانه | I6: مدفوع اسانسير | K6: الصيانة مستحقة سابقا | L6: م. اسانسير مستحقة سابقا | N6: اجمالي الصيانة المستحقة | O6: اجمالي م. اسانسير المستحقة | R6: م | S6: بيان | T6: المبلغ | U6: المستند
C7: 1 | D7: مريم اسحاق | E7: A1 | F7: -500 | H7: 500 | K7: -500 | L7: 0 | N7: =F7+H7+K7 -> -500 | O7: =G7+I7+L7 -> 0 | R7: 1 | S7: راتب الحارس | T7: -3000 | U7: إيصال
C8: 2 | D8: وليد مدحت | E8: A2 | F8: -500 | H8: 500 | K8: 0 | L8: 0 | N8: =F8+H8+K8 -> 0 | O8: =G8+I8+L8 -> 0 | R8: 2 | S8: فاتورة مياة شهر مايو | T8: -1800
C9: 3 | D9: ناريمان ظريف | E9: B1 | F9: -300 | K9: -6000 | L9: 0 | N9: =F9+H9+K9 -> -6300 | O9: =G9+I9+L9 -> 0 | R9: 3 | S9: كهرباء | T9: -2500 | U9: إيصال
C10: 4 | D10: هند صادق | E10: B2 | F10: -500 | H10: 500 | K10: 0 | L10: 0 | N10: =F10+H10+K10 -> 0 | O10: =G10+I10+L10 -> 0 | R10: 4 | S10: غيار ممسحة | T10: -125
C11: 5 | D11: شريف جداره | E11: A11 | F11: -500 | G11: -100 | H11: 1000 | I11: 200 | K11: -500 | L11: -100 | N11: =F11+H11+K11 -> 0 | O11: =G11+I11+L11 -> 0 | R11: 5 | S11: اجرة الجنايني | T11: -400 | U11: فاتورة
C12: 6 | D12: سامح السعيد | E12: A12 | F12: -500 | G12: -100 | H12: 500 | I12: 100 | K12: 0 | L12: 0 | N12: =F12+H12+K12 -> 0 | O12: =G12+I12+L12 -> 0 | R12: 6 | S12: عيديه | T12: -1500 | U12: إيصال
C13: 7 | D13: احمد يونس | E13: A13 | F13: -300 | K13: -3300 | L13: 0 | N13: =F13+H13+K13 -> -3600 | O13: =G13+I13+L13 -> 0 | R13: 7 | S13: مستلزمات نظافة | T13: -500 | U13: إيصال
C14: 8 | D14: محمد ابو بكر | E14: B11 | F14: -300 | H14: 600 | K14: -300 | L14: 0 | N14: =F14+H14+K14 -> 0 | O14: =G14+I14+L14 -> 0 | R14: 8 | S14: باج جراج + سيكوريت | T14: -850 | U14: إيصال
C15: 9 | D15: خالد خشبه | E15: B12 | F15: -500 | H15: 500 | K15: 0 | L15: 0 | N15: =F15+H15+K15 -> 0 | O15: =G15+I15+L15 -> 0 | R15: 9 | S15: لمبات | T15: -465 | U15: إيصال
C16: 10 | D16: خالد عبد الصمد | E16: B13 | F16: -500 | G16: -100 | H16: 1000 | I16: 200 | K16: -1000 | L16: -200 | N16: =F16+H16+K16 -> -500 | O16: =G16+I16+L16 -> -100 | R16: 10 | U16: إيصال
C17: 11 | D17: أشرف علوي | E17: A21 | F17: -500 | G17: -100 | H17: 2000 | I17: 400 | K17: -1500 | L17: -300 | N17: =F17+H17+K17 -> 0 | O17: =G17+I17+L17 -> 0 | S17: الإجمالي | T17: =SUM(T7:T16) -> -11140
C18: 12 | D18: ايهاب محمود | E18: A23 | F18: -500 | G18: -100 | H18: 500 | I18: 100 | K18: 0 | L18: 0 | N18: =F18+H18+K18 -> 0 | O18: =G18+I18+L18 -> 0
C19: 13 | D19: أسامه حسين | E19: B21 | F19: -500 | G19: -100 | K19: 2200 | L19: 800 | N19: =F19+H19+K19 -> 1700 | O19: =G19+I19+L19 -> 700 | R19: حســـــــــــــــــــــــــــــــــــــــــــــاب ختامـــــــــــي
C20: 14 | D20: مي اسامة | E20: B22 | F20: -500 | G20: -100 | H20: 1000 | I20: 200 | K20: -500 | L20: -100 | N20: =F20+H20+K20 -> 0 | O20: =G20+I20+L20 -> 0
C21: 15 | D21: محمد هلال | E21: B23 | F21: -500 | G21: -100 | H21: 1500 | K21: -1000 | L21: -1700 | N21: =F21+H21+K21 -> 0 | O21: =G21+I21+L21 -> -1800 | R21: م | T21: المبلغ | U21: =600+600+600+600+600+600+500+500+500+500+2400+1200+1500+1200 -> 11900
C22: 16 | D22: وجدي محروس | E22: A31 | F22: -500 | G22: -100 | K22: -1000 | L22: -200 | N22: =F22+H22+K22 -> -1500 | O22: =G22+I22+L22 -> -300 | R22: 1 | S22: فائض مرحل | T22: =Feb.!T27 -> 30241 | U22: 1800
C23: 17 | D23: عمرو عبدالرازق | E23: A32 | F23: -500 | G23: -100 | K23: -500 | L23: -100 | N23: =F23+H23+K23 -> -1000 | O23: =G23+I23+L23 -> -200 | R23: 2 | S23: إيرادات شهر مارس 2026 | T23: =H33 -> 13200
C24: 18 | D24: مدام اميرة | E24: A33 | F24: -300 | K24: -600 | L24: 0 | N24: =F24+H24+K24 -> -900 | O24: =G24+I24+L24 -> 0 | R24: 3 | S24: مصروفات شهر مارس 2026 | T24: =T17 -> -11140
C25: 19 | D25: ابراهيم محمد | E25: B31 | F25: -500 | G25: -100 | H25: 500 | I25: 100 | K25: 0 | L25: 0 | N25: =F25+H25+K25 -> 0 | O25: =G25+I25+L25 -> 0 | R25: الإجمالي | T25: =SUM(T22:T24) -> 32301
C26: 20 | D26: مصطفى عبد الصبور | E26: B32 | F26: -500 | G26: -100 | H26: 600 | I26: 600 | K26: -100 | L26: -400 | N26: =F26+H26+K26 -> 0 | O26: =G26+I26+L26 -> 100
C27: 21 | D27: هناء سلامه | E27: B33 | F27: -500 | G27: -100 | K27: 500 | L27: 100 | N27: =F27+H27+K27 -> 0 | O27: =G27+I27+L27 -> 0 | R27: م | S27: بيان الاسانسير | T27: المبلغ
C28: 22 | D28: علي محمد نور الدين | E28: A41 | F28: -500 | G28: -100 | H28: 500 | I28: 100 | K28: 0 | L28: 0 | N28: =F28+H28+K28 -> 0 | O28: =G28+I28+L28 -> 0 | R28: 1 | S28: فائض مرحل | T28: =Feb.!T33 -> 37580
C29: 23 | D29: محمد شاكر | E29: A43 | F29: -500 | G29: -100 | H29: 500 | I29: 100 | K29: 0 | L29: 0 | N29: =F29+H29+K29 -> 0 | O29: =G29+I29+L29 -> 0 | R29: 2 | S29: إيرادات الشهر الجارى | T29: =I33 -> 2300
C30: 24 | D30: محمد السيسي | E30: B41 | F30: -500 | G30: -100 | H30: 500 | I30: 100 | K30: -500 | L30: -100 | N30: =F30+H30+K30 -> -500 | O30: =G30+I30+L30 -> -100 | R30: 3 | S30: مصروفات الشهر الجارى | T30: -700
C31: 25 | D31: حسام رياض | E31: B42 | F31: -500 | G31: -100 | H31: 500 | I31: 100 | K31: 0 | L31: 0 | N31: =F31+H31+K31 -> 0 | O31: =G31+I31+L31 -> 0 | R31: الإجمالي | S31: الإجمالي | T31: =SUM(T28:T30) -> 39180
C32: 26 | D32: ساره عادل | E32: B43 | F32: -300 | G32: -100 | K32: -600 | L32: -200 | N32: =F32+H32+K32 -> -900 | O32: =G32+I32+L32 -> -300
C33: الإجـــــــــــــــــــــــــــــــــــــــــــــــــــــــــــــــــــــمالي | F33: =SUM(F7:F32) -> -12000 | G33: =SUM(G7:G32) -> -1800 | H33: =SUM(H7:H32) -> 13200 | I33: =SUM(I7:I32) -> 2300 | K33: =SUM(K7:K32) -> -15200 | L33: =SUM(L7:L32) -> -2500 | N33: =SUM(N7:N32) -> -14000 | O33: =SUM(O7:O32) -> -2000 | R33: الإجمالي (صيانة + اسانسير) | T33: =T31+T25 -> 71481
N35: =N33-K33 -> 1200
H36: =H33+I33 -> 15500 | N36: =K33+H33+F33 -> -14000 | R36: الصندوق | S36: المبلغ
H37: -1800 | N37: 27100 | R37: رصيد متوفر مع ا/ إيهاب مهدي | S37: =52978+600+600+600+600+600+600+600+500+500+500+2400+1500+1200+600 -> 64378
N38: =N37+N33 -> 13100 | R38: رصيد متوفر مع ا/ إبراهيم محمد | S38: =14843+1200+600+1200+600+500+T24+T30 -> 7103 | U38: =S38-Feb.!S41 -> -7740
H40: =Feb.!S40+Feb.!S41 -> 67821 | R40: الإجمالي | S40: =SUM(S37:S39) -> 71481
H41: =H33+I33 -> 15500
H42: =T17+T30 -> -11840 | R42: الفــــرق | S42: =S40-T33 -> 0

Sheet Apr.
B1: -1
C3: عمارة 14 بالم الزهراء - الشطر السابع | Q3: عمارة 14 بالم الزهراء - الشطر السابع
C4: كشف ايرادات ومصروفات شهر ابريل 2026 | Q4: كشف مصروفات شهر ابريل 2026
C6: م | D6: الاسم | E6: الشقة | F6: ايرادات الشهر الجاري | G6: ايرادات الأسانسير | H6: مدفوع صيانه | I6: مدفوع اسانسير | J6: الصيانة مستحقة سابقا | K6: م. اسانسير مستحقة سابقا | M6: اجمالي الصيانة المستحقة | N6: اجمالي م. اسانسير المستحقة | Q6: م | R6: بيان | S6: المبلغ | T6: المستند
A8: 1500 | B8: =A8-May!A8 -> 0 | C8: 1 | D8: مريم اسحاق | E8: A1 | F8: -500 | H8: 500 | J8: -500 | K8: 0 | M8: =F8+H8+J8 -> -500 | N8: =G8+I8+K8 -> 0 | Q8: 1 | R8: راتب الحارس | S8: -3000 | T8: إيصال | X8: =M8/F8 -> 1 | Y8: =IFERROR((N8/G8),0) -> 0
C9: 2 | D9: وليد مدحت | E9: A2 | F9: -500 | H9: 500 | J9: 0 | K9: 0 | M9: =F9+H9+J9 -> 0 | N9: =G9+I9+K9 -> 0 | Q9: 2 | R9: فاتورة مياة شهر مايو | S9: -1780 | X9: =M9/F9 -> 0 | Y9: =IFERROR((N9/G9),0) -> 0
C10: 3 | D10: ناريمان ظريف | E10: B1 | F10: -300 | J10: -6300 | K10: 0 | M10: =F10+H10+J10 -> -6600 | N10: =G10+I10+K10 -> 0 | Q10: 3 | R10: كهرباء | S10: -2000 | T10: إيصال | X10: =M10/F10 -> 22 | Y10: =IFERROR((N10/G10),0) -> 0
C11: 4 | D11: هند صادق | E11: B2 | F11: -500 | H11: 500 | J11: 0 | K11: 0 | M11: =F11+H11+J11 -> 0 | N11: =G11+I11+K11 -> 0 | Q11: 4 | R11: غيار ممسحة | S11: -300 | X11: =M11/F11 -> 0 | Y11: =IFERROR((N11/G11),0) -> 0
C12: 5 | D12: شريف جداره | E12: A11 | F12: -500 | G12: -100 | H12: 500 | I12: 100 | J12: 0 | K12: 0 | M12: =F12+H12+J12 -> 0 | N12: =G12+I12+K12 -> 0 | Q12: 5 | R12: اجرة الجنايني | S12: -400 | T12: فاتورة | X12: =M12/F12 -> 0 | Y12: =IFERROR((N12/G12),0) -> 0
A13: 600 | C13: 6 | D13: سامح السعيد | E13: A12 | F13: -500 | G13: -100 | H13: 500 | I13: 100 | J13: 0 | K13: 0 | M13: =F13+H13+J13 -> 0 | N13: =G13+I13+K13 -> 0 | Q13: 6 | R13: فك زينه | S13: -350 | T13: إيصال | X13: =M13/F13 -> 0 | Y13: =IFERROR((N13/G13),0) -> 0
C14: 7 | D14: احمد يونس | E14: A13 | F14: -300 | J14: -3600 | K14: 0 | M14: =F14+H14+J14 -> -3900 | N14: =G14+I14+K14 -> 0 | Q14: 7 | R14: نظافة | S14: -500 | T14: إيصال | X14: =M14/F14 -> 13 | Y14: =IFERROR((N14/G14),0) -> 0
C15: 8 | D15: محمد ابو بكر | E15: B11 | F15: -300 | H15: 300 | J15: 0 | K15: 0 | M15: =F15+H15+J15 -> 0 | N15: =G15+I15+K15 -> 0 | Q15: 8 | R15: نتصليح موتور الغاطس الجراج | S15: -500 | X15: =M15/F15 -> 0 | Y15: =IFERROR((N15/G15),0) -> 0
C16: 9 | D16: خالد خشبه | E16: B12 | F16: -500 | H16: 500 | J16: 0 | K16: 0 | M16: =F16+H16+J16 -> 0 | N16: =G16+I16+K16 -> 0 | Q16: 9 | R16: مصاريف موتور المياه | S16: -250 | X16: =M16/F16 -> 0 | Y16: =IFERROR((N16/G16),0) -> 0
C17: 10 | D17: خالد عبد الصمد | E17: B13 | F17: -500 | G17: -100 | H17: 1000 | I17: 200 | J17: -500 | K17: -100 | M17: =F17+H17+J17 -> 0 | N17: =G17+I17+K17 -> 0 | Q17: 10 | R17: شراء لمبات المدخل وتركيب 100 ج | X17: =M17/F17 -> 0 | Y17: =IFERROR((N17/G17),0) -> 0
C18: 11 | D18: أشرف علوي | E18: A21 | F18: -500 | G18: -100 | J18: 0 | K18: 0 | M18: =F18+H18+J18 -> -500 | N18: =G18+I18+K18 -> -100 | R18: الإجمالي | S18: =SUM(S8:S17) -> -9080 | X18: =M18/F18 -> 1 | Y18: =IFERROR((N18/G18),0) -> 1
C19: 12 | D19: ايهاب محمود | E19: A23 | F19: -500 | G19: -100 | H19: 500 | I19: 100 | J19: 0 | K19: 0 | M19: =F19+H19+J19 -> 0 | N19: =G19+I19+K19 -> 0 | X19: =M19/F19 -> 0 | Y19: =IFERROR((N19/G19),0) -> 0
C20: 13 | D20: أسامه حسين | E20: B21 | F20: -500 | G20: -100 | J20: 1700 | K20: 700 | M20: =F20+H20+J20 -> 1200 | N20: =G20+I20+K20 -> 600 | Q20: حســـــــــــــــــــــــــــــــــــــــــــــاب ختامـــــــــــي | X20: =M20/F20 -> -2.4 | Y20: =IFERROR((N20/G20),0) -> -6
A21: 2300 | C21: 14 | D21: مي اسامة | E21: B22 | F21: -500 | G21: -100 | H21: 500 | I21: 100 | J21: 0 | K21: 0 | M21: =F21+H21+J21 -> 0 | N21: =G21+I21+K21 -> 0 | X21: =M21/F21 -> 0 | Y21: =IFERROR((N21/G21),0) -> 0
A22: 1500 | C22: 15 | D22: محمد هلال | E22: B23 | F22: -500 | G22: -100 | H22: 500 | I22: 100 | J22: 0 | K22: -1800 | M22: =F22+H22+J22 -> 0 | N22: =G22+I22+K22 -> -1800 | Q22: م | R22: بيان صيانة | S22: المبلغ | X22: =M22/F22 -> 0 | Y22: =IFERROR((N22/G22),0) -> 18
C23: 16 | D23: وجدي محروس | E23: A31 | F23: -500 | G23: -100 | J23: -1500 | K23: -300 | M23: =F23+H23+J23 -> -2000 | N23: =G23+I23+K23 -> -400 | Q23: 1 | R23: فائض مرحل | S23: =Mar.!T25 -> 32301 | X23: =M23/F23 -> 4 | Y23: =IFERROR((N23/G23),0) -> 4
C24: 17 | D24: عمرو عبدالرازق | E24: A32 | F24: -500 | G24: -100 | J24: -1000 | K24: -200 | M24: =F24+H24+J24 -> -1500 | N24: =G24+I24+K24 -> -300 | Q24: 2 | R24: إيرادات الشهر الجارى | S24: =H35 -> 9500 | X24: =M24/F24 -> 3 | Y24: =IFERROR((N24/G24),0) -> 3
C25: 18 | D25: مدام اميرة | E25: A33 | F25: -300 | J25: -900 | K25: 0 | M25: =F25+H25+J25 -> -1200 | N25: =G25+I25+K25 -> 0 | Q25: 3 | R25: مصروفات الشهر الجارى | S25: =S18 -> -9080 | X25: =M25/F25 -> 4 | Y25: =IFERROR((N25/G25),0) -> 0
A26: 1200 | C26: 19 | D26: ابراهيم محمد | E26: B31 | F26: -500 | G26: -100 | H26: 500 | I26: 100 | J26: 0 | K26: 0 | M26: =F26+H26+J26 -> 0 | N26: =G26+I26+K26 -> 0 | Q26: الإجمالي | S26: =SUM(S23:S25) -> 32721 | X26: =M26/F26 -> 0 | Y26: =IFERROR((N26/G26),0) -> 0
A27: 2300 | C27: 20 | D27: مصطفى عبد الصبور | E27: B32 | F27: -500 | G27: -100 | J27: 0 | K27: 100 | M27: =F27+H27+J27 -> -500 | N27: =G27+I27+K27 -> 0 | X27: =M27/F27 -> 1 | Y27: =IFERROR((N27/G27),0) -> 0
C28: 21 | D28: هناء سلامه | E28: B33 | F28: -500 | G28: -100 | J28: 0 | K28: 0 | M28: =F28+H28+J28 -> -500 | N28: =G28+I28+K28 -> -100 | Q28: م | R28: بيان الاسانسير | S28: المبلغ | X28: =M28/F28 -> 1 | Y28: =IFERROR((N28/G28),0) -> 1
C29: 22 | D29: علي محمد نور الدين | E29: A41 | F29: -500 | G29: -100 | H29: 500 | I29: 100 | J29: 0 | K29: 0 | M29: =F29+H29+J29 -> 0 | N29: =G29+I29+K29 -> 0 | Q29: 1 | R29: فائض مرحل | S29: =Mar.!T31 -> 39180 | X29: =M29/F29 -> 0 | Y29: =IFERROR((N29/G29),0) -> 0
C30: 23 | D30: محمد شاكر | E30: A43 | F30: -500 | G30: -100 | H30: 500 | I30: 100 | J30: 0 | K30: 0 | M30: =F30+H30+J30 -> 0 | N30: =G30+I30+K30 -> 0 | Q30: 2 | R30: إيرادات الشهر الجارى | S30: =I35 -> 1600 | X30: =M30/F30 -> 0 | Y30: =IFERROR((N30/G30),0) -> 0
A31: 1200 | C31: 24 | D31: محمد السيسي | E31: B41 | F31: -500 | G31: -100 | H31: 500 | I31: 100 | J31: -500 | K31: -100 | M31: =F31+H31+J31 -> -500 | N31: =G31+I31+K31 -> -100 | Q31: 3 | R31: مصروفات الشهر الجارى | S31: =-200-500 -> -700 | X31: =M31/F31 -> 1 | Y31: =IFERROR((N31/G31),0) -> 1
A32: 1200 | C32: 25 | D32: حسام رياض | E32: B42 | F32: -500 | G32: -100 | H32: 500 | I32: 100 | J32: 0 | K32: 0 | M32: =F32+H32+J32 -> 0 | N32: =G32+I32+K32 -> 0 | Q32: الإجمالي | S32: =SUM(S29:S31) -> 40080 | X32: =M32/F32 -> 0 | Y32: =IFERROR((N32/G32),0) -> 0
C33: 26 | D33: ساره عادل | E33: B43 | F33: -300 | G33: -100 | H33: 1200 | I33: 400 | J33: -900 | K33: -300 | M33: =F33+H33+J33 -> 0 | N33: =G33+I33+K33 -> 0 | X33: =M33/F33 -> 0 | Y33: =IFERROR((N33/G33),0) -> 0
X34: =M34/F34 -> #DIV/0! | Y34: =IFERROR((N34/G34),0) -> 0
C35: الإجـــــــــــــــــــــــــــــــــــــــــــــــــــــــــــــــــــــمالي | F35: =SUM(F8:F33) -> -12000 | G35: =SUM(G8:G33) -> -1800 | H35: =SUM(H8:H33) -> 9500 | I35: =SUM(I8:I33) -> 1600 | J35: =SUM(J8:J33) -> -14000 | K35: =SUM(K8:K33) -> -2000 | M35: =SUM(M8:M33) -> -16500 | N35: =SUM(N8:N33) -> -2200 | Q35: الإجمالي (صيانة + اسانسير) | S35: =S32+S26 -> 72801
A36: =SUM(A8:A32) -> 11800
F37: =F35+H35 -> -2500 | R37: 24180 | S37: =S35+S43+S44 -> 145602
I38: =I35+Mar.!I33+Feb.!I33+January!I33 -> 7700 | K38: 50000 | S38: =S26 -> 32721
D39: 26900 | I39: =I38-S38 -> -25021 | K39: 11800 | S39: =S32 -> 40080
D40: 11800 | K40: =SUM(K38:K39) -> 61800
K41: =-K40=S43 -> FALSE
R42: العهـــــدة | S42: المبلغ
R43: رصيد متوفر مع ا/ إيهاب مهدي | S43: =Mar.!S37+1600+600+600+600+600+600+500+500+600+500+300+600+600+1200-40000 -> 33778
...

Sheet May
B1: -1
C3: عمارة 14 بالم الزهراء - الشطر السابع | Q3: عمارة 14 بالم الزهراء - الشطر السابع
C4: كشف ايرادات ومصروفات شهر مايو 2026 | Q4: كشف مصروفات شهر مايو 2026
C6: م | D6: الاسم | E6: الشقة | F6: ايرادات الشهر الجاري | G6: ايرادات الأسانسير | H6: مدفوع صيانه | I6: مدفوع اسانسير | J6: الصيانة مستحقة سابقا | K6: م. اسانسير مستحقة سابقا | M6: اجمالي الصيانة المستحقة | N6: اجمالي م. اسانسير المستحقة | Q6: م | R6: بيان | S6: المبلغ | T6: المستند
A8: 1500 | C8: 1 | D8: مريم اسحاق | E8: A1 | F8: -500 | H8: 500 | J8: -500 | K8: 0 | M8: =F8+H8+J8 -> -500 | N8: =G8+I8+K8 -> 0 | Q8: 1 | R8: راتب الحارس | S8: -3000 | T8: إيصال
C9: 2 | D9: وليد مدحت | E9: A2 | F9: -500 | H9: 500 | J9: 0 | K9: 0 | M9: =F9+H9+J9 -> 0 | N9: =G9+I9+K9 -> 0 | Q9: 2 | R9: فاتورة مياة شهر مايو | S9: -3620
C10: 3 | D10: ناريمان ظريف | E10: B1 | F10: -300 | J10: -6600 | K10: 0 | M10: =F10+H10+J10 -> -6900 | N10: =G10+I10+K10 -> 0 | Q10: 3 | R10: كهرباء | S10: -3000 | T10: إيصال
A11: 500 | C11: 4 | D11: هند صادق | E11: B2 | F11: -500 | H11: 500 | J11: 0 | K11: 0 | M11: =F11+H11+J11 -> 0 | N11: =G11+I11+K11 -> 0 | Q11: 4 | R11: غيار ممسحة | S11: -300
A12: 600 | C12: 5 | D12: شريف جداره | E12: A11 | F12: -500 | G12: -100 | H12: 500 | I12: 100 | J12: 0 | K12: 0 | M12: =F12+H12+J12 -> 0 | N12: =G12+I12+K12 -> 0 | Q12: 5 | R12: اجرة الجنايني | S12: -400 | T12: فاتورة
A13: 1200 | C13: 6 | D13: سامح السعيد | E13: A12 | F13: -500 | G13: -100 | H13: 500 | I13: 100 | J13: 0 | K13: 0 | M13: =F13+H13+J13 -> 0 | N13: =G13+I13+K13 -> 0 | Q13: 6 | R13: نظافة | S13: -500 | T13: إيصال
C14: 7 | D14: احمد يونس | E14: A13 | F14: -300 | H14: 4200 | J14: -3900 | K14: 0 | M14: =F14+H14+J14 -> 0 | N14: =G14+I14+K14 -> 0 | Q14: 7 | R14: عيدية صلاح | S14: -1500 | T14: إيصال
C15: 8 | D15: محمد ابو بكر | E15: B11 | F15: -300 | H15: 300 | J15: 0 | K15: 0 | M15: =F15+H15+J15 -> 0 | N15: =G15+I15+K15 -> 0 | Q15: 8 | R15: انتركم | S15: -700
C16: 9 | D16: خالد خشبه | E16: B12 | F16: -500 | H16: 500 | J16: 0 | K16: 0 | M16: =F16+H16+J16 -> 0 | N16: =G16+I16+K16 -> 0 | Q16: 9 | R16: مبيدات رش | S16: -1335 | W16: =13400-H35-I35 -> -1900
A17: 5800 | C17: 10 | D17: خالد عبد الصمد | E17: B13 | F17: -500 | G17: -100 | J17: 0 | K17: 0 | M17: =F17+H17+J17 -> -500 | N17: =G17+I17+K17 -> -100 | Q17: 10 | R17: شراء لمبات المدخل وتركيب 100 ج
A18: 3000 | C18: 11 | D18: أشرف علوي | E18: A21 | F18: -500 | G18: -100 | J18: -500 | K18: -100 | M18: =F18+H18+J18 -> -1000 | N18: =G18+I18+K18 -> -200 | R18: الإجمالي | S18: =SUM(S8:S17) -> -14355
A19: 1200 | C19: 12 | D19: ايهاب محمود | E19: A23 | F19: -500 | G19: -100 | H19: 500 | I19: 100 | J19: 0 | K19: 0 | M19: =F19+H19+J19 -> 0 | N19: =G19+I19+K19 -> 0
C20: 13 | D20: أسامه حسين | E20: B21 | F20: -500 | G20: -100 | J20: 1200 | K20: 600 | M20: =F20+H20+J20 -> 700 | N20: =G20+I20+K20 -> 500 | Q20: حســـــــــــــــــــــــــــــــــــــــــــــاب ختامـــــــــــي
A21: 3100 | C21: 14 | D21: مي اسامة | E21: B22 | F21: -500 | G21: -100 | H21: 500 | I21: 100 | J21: 0 | K21: 0 | M21: =F21+H21+J21 -> 0 | N21: =G21+I21+K21 -> 0
A22: 1500 | C22: 15 | D22: محمد هلال | E22: B23 | F22: -500 | G22: -100 | H22: 500 | I22: 100 | J22: 0 | K22: -1800 | M22: =F22+H22+J22 -> 0 | N22: =G22+I22+K22 -> -1800 | Q22: م | R22: بيان صيانة | S22: المبلغ
C23: 16 | D23: وجدي محروس | E23: A31 | F23: -500 | G23: -100 | J23: -2000 | K23: -400 | M23: =F23+H23+J23 -> -2500 | N23: =G23+I23+K23 -> -500 | Q23: 1 | R23: فائض مرحل | S23: =Apr.!S26 -> 32721
A24: 1200 | C24: 17 | D24: عمرو عبدالرازق | E24: A32 | F24: -500 | G24: -100 | J24: -1500 | K24: -300 | M24: =F24+H24+J24 -> -2000 | N24: =G24+I24+K24 -> -400 | Q24: 2 | R24: إيرادات الشهر الجارى | S24: =H35 -> 13800
C25: 18 | D25: مدام اميرة | E25: A33 | F25: -300 | J25: -1200 | K25: 0 | M25: =F25+H25+J25 -> -1500 | N25: =G25+I25+K25 -> 0 | Q25: 3 | R25: مصروفات الشهر الجارى | S25: =S18 -> -14355
A26: 600 | C26: 19 | D26: ابراهيم محمد | E26: B31 | F26: -500 | G26: -100 | H26: 500 | I26: 100 | J26: 0 | K26: 0 | M26: =F26+H26+J26 -> 0 | N26: =G26+I26+K26 -> 0 | Q26: الإجمالي | S26: =SUM(S23:S25) -> 32166
A27: 3100 | C27: 20 | D27: مصطفى عبد الصبور | E27: B32 | F27: -500 | G27: -100 | H27: 500 | I27: 100 | J27: -500 | K27: 0 | M27: =F27+H27+J27 -> -500 | N27: =G27+I27+K27 -> 0 | Y27: 50000
C28: 21 | D28: هناء سلامه | E28: B33 | F28: -500 | G28: -100 | H28: 1000 | I28: 200 | J28: -500 | K28: -100 | M28: =F28+H28+J28 -> 0 | N28: =G28+I28+K28 -> 0 | Q28: م | R28: بيان الاسانسير | S28: المبلغ | Y28: 26900
A29: 600 | C29: 22 | D29: علي محمد نور الدين | E29: A41 | F29: -500 | G29: -100 | H29: 500 | I29: 100 | J29: 0 | K29: 0 | M29: =F29+H29+J29 -> 0 | N29: =G29+I29+K29 -> 0 | Q29: 1 | R29: فائض مرحل | S29: =Apr.!S32 -> 40080
C30: 23 | D30: محمد شاكر | E30: A43 | F30: -500 | G30: -100 | H30: 500 | I30: 100 | J30: 0 | K30: 0 | M30: =F30+H30+J30 -> 0 | N30: =G30+I30+K30 -> 0 | Q30: 2 | R30: إيرادات الشهر الجارى | S30: =I35 -> 1500
A31: 1800 | C31: 24 | D31: محمد السيسي | E31: B41 | F31: -500 | G31: -100 | H31: 1000 | I31: 200 | J31: -500 | K31: -100 | M31: =F31+H31+J31 -> 0 | N31: =G31+I31+K31 -> 0 | Q31: 3 | R31: مصروفات الشهر الجارى | S31: =-500-300-900 -> -1700
A32: 2000 | C32: 25 | D32: حسام رياض | E32: B42 | F32: -500 | G32: -100 | H32: 500 | I32: 100 | J32: 0 | K32: 0 | M32: =F32+H32+J32 -> 0 | N32: =G32+I32+K32 -> 0 | Q32: الإجمالي | S32: =SUM(S29:S31) -> 39880
A33: 400 | C33: 26 | D33: ساره عادل | E33: B43 | F33: -300 | G33: -100 | H33: 300 | I33: 100 | J33: 0 | K33: 0 | M33: =F33+H33+J33 -> 0 | N33: =G33+I33+K33 -> 0 | X33: =-S31-S18 -> 16055
B34: =A34-Apr.!A34 -> 0
A35: =A40+S43 -> 73678 | C35: الإجـــــــــــــــــــــــــــــــــــــــــــــــــــــــــــــــــــــمالي | F35: =SUM(F8:F33) -> -12000 | G35: =SUM(G8:G33) -> -1800 | H35: =SUM(H8:H33) -> 13800 | I35: =SUM(I8:I33) -> 1500 | J35: =SUM(J8:J33) -> -16500 | K35: =SUM(K8:K33) -> -2200 | M35: =SUM(M8:M33) -> -14700 | N35: =SUM(N8:N33) -> -2500 | Q35: الإجمالي (صيانة + اسانسير) | S35: =S32+S26 -> 72046
AA36: =S43-20000 -> 25578
A37: =A40-Apr.!A36 -> 16300 | F37: =F35+H35 -> 1800 | R37: 24180 | S37: =S35+S43+S44 -> 144092 | AA37: 76900
A38: =-A17+A37 -> 10500 | I38: 50000 | S38: =S26 -> 32166
D39: =-A40 -> -28100 | I39: =SUM(A8:A33) -> 28100 | S39: =S32 -> 39880 | W39: =Apr.!S44 -> 39023 | X39: =W39-S44 -> 12555
A40: =SUM(A8:A33) -> 28100 | G40: 11800 | I40: =SUM(I38:I39) -> 78100 | K40: =-2600-600-600-5800-3000-600-400-800-800-500-1200 -> -16900 | X40: =X33-X39 -> 3500
I41: =-I40=S43 -> FALSE | J41: =I40+S43-20000 -> 103678
R42: العهـــــدة | S42: المبلغ
R43: رصيد متوفر مع ا/ إيهاب مهدي | S43: =Apr.!S43+500+500+1200+600+600+600+600+300+600+500+600+400+4200+600 -> 45578 | V43: =S43-500 -> 45078 | W43: =V43-44778 -> 300 | X43: =S43-44778 -> 800
...

Sheet Jun
B1: -1
